Workbook

Sheet Cover
A1: Micron Technology, Inc. (MU)
A2: Technology · Standard (forward multiples + DCF) · generated 2026-10-13 · data: Yahoo snapshot as of 2026-07-09
A4: Current price | B4: =Assumptions!$B$5
A5: DCF value per share (one lens) | B5: =DCF!$B$24
A6: Upside / downside | B6: =DCF!$B$24/Assumptions!$B$5-1
A7: 12-month price target (report) | B7: 1264.8336
A8: WACC | B8: =WACC!$B$10
A10: How to use
A11: Blue cells are inputs — edit growth, margins, beta, ERP or terminal g
A12: in the Assumptions sheet and everything recalculates live.
A13: Black cells are formulas; green cells link across sheets.
A14: The Sensitivity grid re-runs the full DCF per WACC/g pair.
A15: Not investment advice. Verify source data before relying on outputs.

Sheet Target Price
A1: MU — 12-month price target (lens triangulation)
A2: Blue = inputs (weights, Ke, dividends, Street weight); black = live formulas. Change a weight and the blended fair value and target recalculate. Guardrail exclusions are already reflected in the effective weights.
A4: Lens | B4: Type | C4: Value / share | D4: Low | E4: High | F4: Weight | G4: Status
A5: Discounted cash flow (FCFF) | B5: intrinsic | C5: 490.58791 | D5: 411.25637 | E5: 582.46834 | F5: 0.20289855 | G5: ok — down-weighted: 0.4x the median of the other lenses
A6: Forward P/E | B6: relative | C6: 1269.6633 | D6: 1041.1239 | E6: 1498.2027 | F6: 0.43478261 | G6: ok
A7: Forward EV/EBITDA | B7: relative | C7: 1240.3335 | D7: 1016.2812 | E7: 1464.3858 | F7: 0.36231884 | G7: ok
A9: Weights sum | B9: =SUM(F5:F7)
A10: Blended fair value (today) | B10: =SUMPRODUCT(C5:C7,F5:F7)/SUM(F5:F7)
A11: Cost of equity (Ke) | B11: 0.11381229
A12: Dividends per share (12m) | B12: 0.4622
A13: Model 12-month target = FV×(1+Ke)−DPS | B13: =$B$10*(1+$B$11)-$B$12
A14: Street mean target | B14: 1486
A15: Street weight in target | B15: 0.15
A16: Published 12-month target | B16: =(1-$B$15)*$B$13+$B$15*$B$14
A17: Current price | B17: 948.8
A18: Engine target (incl. plausibility band) | B18: 1264.8336
A20: Guardrails
A21: Discounted cash flow (FCFF) sits 0.4x the lens median and was down-weighted by 60%.
A22: Target anchored 15% to the Street consensus ($1,486.00); model-only target $1,225.80.

Sheet Financial Model
A1: MU — projected P&L & levered FCF (DCF base case)
A2: Blue = consensus-sourced figures; black = live formulas. Revenue and EBIT margin are the DCF base-case drivers; levered FCF = unlevered FCF less after-tax interest.
A4: Line item | B4: FY2026E | C4: FY2027E | D4: FY2028E | E4: FY2029E | F4: FY2030E | G4: FY2031E | H4: FY2032E | I4: FY2033E | J4: FY2034E | K4: FY2035E
A5: Revenue (mn) | B5: 129590 | C5: 234240 | D5: 258619.8 | E5: 279149.08 | F5: 296566.54 | G5: 311606.85 | H5: 324907.14 | I5: 336980.61 | J5: 348222.87 | K5: 356928.44
A6: Revenue growth | B6: — | C6: =C5/B5-1 | D6: =D5/C5-1 | E6: =E5/D5-1 | F6: =F5/E5-1 | G6: =G5/F5-1 | H6: =H5/G5-1 | I6: =I5/H5-1 | J6: =J5/I5-1 | K6: =K5/J5-1
A7: EBIT margin | B7: 0.47348657 | C7: 0.47348657 | D7: 0.43319396 | E7: 0.39290136 | F7: 0.35260875 | G7: 0.31231614 | H7: 0.27202353 | I7: 0.23173092 | J7: 0.23173092 | K7: 0.23173092
A8: EBIT (mn) | B8: =B5*B7 | C8: =C5*C7 | D8: =D5*D7 | E8: =E5*E7 | F8: =F5*F7 | G8: =G5*G7 | H8: =H5*H7 | I8: =I5*I7 | ... K8: =K5*K7
A9: Net income (mn) | B9: 82807.106 | C9: 169002.39 | D9: 90251.465 | E9: 88346.622 | F9: 84215.652 | G9: 78348.499 | H9: 71117.85 | I9: 62790.081 | J9: 64897.742 | K9: 66529.833
A10: EPS | B10: =B9*1000000/1129393151.0 | C10: =C9*1000000/1129393151.0 | D10: =D9*1000000/1129393151.0 | E10: =E9*1000000/1129393151.0 | F10: =F9*1000000/1129393151.0 | G10: =G9*1000000/1129393151.0 | H10: =H9*1000000/1129393151.0 | I10: =I9*1000000/1129393151.0 | ... K10: =K9*1000000/1129393151.0
A12: Levered FCF (mn) | B12: 28805.052 | C12: 59492.039 | D12: 67143.959 | E12: 65886.412 | F12: 62836.082 | G12: 58373.333 | H12: 52795.413 | I12: 46319.255 | J12: 50446.46 | K12: 54487.199
A13: FCF margin | B13: =B12/B5 | C13: =C12/C5 | D13: =D12/D5 | E13: =E12/E5 | F13: =F12/F5 | G13: =G12/G5 | H13: =H12/H5 | I13: =I12/I5 | ... K13: =K12/K5
A15: → Unlevered FCF (before interest) is what the 'DCF' sheet discounts.

Sheet Assumptions
A1: MU — Assumptions & Drivers
A2: Blue cells are inputs — change them and the whole model recalculates. Source: Yahoo snapshot as of 2026-07-09, retrieved 2026-10-13.
A4: Market data
A5: Share price (USD) | B5: 948.8
A6: Diluted shares (mn) | B6: 1129.3932
A7: Total debt (USDmm) | B7: 15278
A8: Cash & ST investments (USDmm) | B8: 10307
A9: Minority interest (USDmm) | B9: 0
A10: Net debt (USDmm) | B10: =Assumptions!$B$7-Assumptions!$B$8
A12: Cost of capital inputs
A13: Risk-free rate (Rf) | B13: 0.043
A14: Equity risk premium (ERP) | B14: 0.046
A15: Country risk premium | B15: 0
A16: Size premium | B16: 0
A17: Beta (levered) | B17: 1.54
A18: Pre-tax cost of debt | B18: 0.049
A19: Tax rate | B19: 0.19097279
A21: Terminal assumptions
A22: Terminal growth (g) | B22: 0.025
A24: Per-year forecast drivers
A25: Driver | B25: FY2026E | C25: FY2027E | D25: FY2028E | E25: FY2029E | F25: FY2030E | G25: FY2031E | H25: FY2032E | I25: FY2033E | J25: FY2034E | K25: FY2035E
A26: Revenue growth | B26: 2.4670127 | C26: 0.80754688 | D26: 0.10408044 | E26: 0.079380143 | F26: 0.062394832 | G26: 0.050714782 | H26: 0.042682925 | I26: 0.03715977 | J26: 0.033361739 | K26: 0.025
A27: EBIT margin | B27: 0.47348657 | C27: 0.47348657 | D27: 0.43319396 | E27: 0.39290136 | F27: 0.35260875 | G27: 0.31231614 | H27: 0.27202353 | I27: 0.23173092 | J27: 0.23173092 | K27: 0.23173092
A28: D&A % of revenue | B28: 0.31593122 | C28: 0.31593122 | D28: 0.31593122 | E28: 0.31593122 | F28: 0.31593122 | G28: 0.31593122 | H28: 0.31593122 | I28: 0.31593122 | J28: 0.31593122 | K28: 0.31593122
A29: Capex % of revenue | B29: 0.41111563 | C29: 0.40404993 | D29: 0.39698423 | E29: 0.38991853 | F29: 0.38285284 | G29: 0.37578714 | H29: 0.36872144 | I29: 0.36165574 | J29: 0.35459004 | K29: 0.34752434
A30: ΔNWC % of Δrevenue | B30: 0.088006936

Sheet WACC
A1: Cost of capital (CAPM)
A2: All formulas reference the Assumptions sheet.
A4: Cost of equity (Ke = Rf + β·ERP + CRP + size) | B4: =Assumptions!$B$13+Assumptions!$B$17*Assumptions!$B$14+Assumptions!$B$15+Assumptions!$B$16
A5: After-tax cost of debt (Kd·(1−t)) | B5: =Assumptions!$B$18*(1-Assumptions!$B$19)
A6: Market value of equity (mm) | B6: =Assumptions!$B$5*Assumptions!$B$6
A7: Debt (book, mm) | B7: =Assumptions!$B$7
A8: Weight of equity | B8: =WACC!$B$6/(WACC!$B$6+WACC!$B$7)
A9: Weight of debt | B9: =1-WACC!$B$8
A10: WACC | B10: =WACC!$B$8*WACC!$B$4+WACC!$B$9*WACC!$B$5

Sheet Model
A1: Operating model (USDmm)
A2: Shaded columns are reported actuals (blue hardcodes, sourced); unshaded are forecast formulas driven by the Assumptions sheet.
A4: Line item | B4: FY2022A | C4: FY2023A | D4: FY2024A | E4: FY2025A | F4: FY2026E | G4: FY2027E | H4: FY2028E | I4: FY2029E | J4: FY2030E | K4: FY2031E | L4: FY2032E | M4: FY2033E | N4: FY2034E | O4: FY2035E
A5: Revenue | B5: 30758 | C5: 15540 | D5: 25111 | E5: 37378 | F5: =E5*(1+Assumptions!B$26) | G5: =F5*(1+Assumptions!C$26) | H5: =G5*(1+Assumptions!D$26) | I5: =H5*(1+Assumptions!E$26) | J5: =I5*(1+Assumptions!F$26) | K5: =J5*(1+Assumptions!G$26) | L5: =K5*(1+Assumptions!H$26) | M5: =L5*(1+Assumptions!I$26) | ... O5: =N5*(1+Assumptions!K$26)
A6: growth % | C6: =C5/B5-1 | D6: =D5/C5-1 | E6: =E5/D5-1 | F6: =F5/E5-1 | G6: =G5/F5-1 | H6: =H5/G5-1 | I6: =I5/H5-1 | J6: =J5/I5-1 | ... O6: =O5/N5-1
A7: EBIT | B7: 9709 | C7: -5405 | D7: 1305 | E7: 9809 | F7: =F5*Assumptions!B$27 | G7: =G5*Assumptions!C$27 | H7: =H5*Assumptions!D$27 | I7: =I5*Assumptions!E$27 | J7: =J5*Assumptions!F$27 | K7: =K5*Assumptions!G$27 | L7: =L5*Assumptions!H$27 | M7: =M5*Assumptions!I$27 | ... O7: =O5*Assumptions!K$27
A8: EBIT margin % | B8: =B7/B5 | C8: =C7/C5 | D8: =D7/D5 | E8: =E7/E5 | F8: =F7/F5 | G8: =G7/G5 | H8: =H7/H5 | I8: =I7/I5 | ... O8: =O7/O5
A9: D&A | B9: 7116 | C9: 7756 | D9: 7780 | E9: 8352 | F9: =F5*Assumptions!B$28 | G9: =G5*Assumptions!C$28 | H9: =H5*Assumptions!D$28 | I9: =I5*Assumptions!E$28 | J9: =J5*Assumptions!F$28 | K9: =K5*Assumptions!G$28 | L9: =L5*Assumptions!H$28 | M9: =M5*Assumptions!I$28 | ... O9: =O5*Assumptions!K$28
A10: EBITDA | B10: =B7+B9 | C10: =C7+C9 | D10: =D7+D9 | E10: =E7+E9 | F10: =F7+F9 | G10: =G7+G9 | H10: =H7+H9 | I10: =I7+I9 | ... O10: =O7+O9
A11: NOPAT (EBIT×(1−t)) | B11: =B7*(1-Assumptions!$B$19) | C11: =C7*(1-Assumptions!$B$19) | D11: =D7*(1-Assumptions!$B$19) | E11: =E7*(1-Assumptions!$B$19) | F11: =F7*(1-Assumptions!$B$19) | G11: =G7*(1-Assumptions!$B$19) | H11: =H7*(1-Assumptions!$B$19) | I11: =I7*(1-Assumptions!$B$19) | ... O11: =O7*(1-Assumptions!$B$19)
A12: Capex | B12: 12067 | C12: 7676 | D12: 8386 | E12: 15857 | F12: =F5*Assumptions!B$29 | G12: =G5*Assumptions!C$29 | H12: =H5*Assumptions!D$29 | I12: =I5*Assumptions!E$29 | J12: =J5*Assumptions!F$29 | K12: =K5*Assumptions!G$29 | L12: =L5*Assumptions!H$29 | M12: =M5*Assumptions!I$29 | ... O12: =O5*Assumptions!K$29
A13: Δ Net working capital | B13: 1255 | C13: 2911 | D13: 1165 | E13: 666 | F13: =(F5-E5)*Assumptions!$B$30 | G13: =(G5-F5)*Assumptions!$B$30 | H13: =(H5-G5)*Assumptions!$B$30 | I13: =(I5-H5)*Assumptions!$B$30 | J13: =(J5-I5)*Assumptions!$B$30 | K13: =(K5-J5)*Assumptions!$B$30 | L13: =(L5-K5)*Assumptions!$B$30 | M13: =(M5-L5)*Assumptions!$B$30 | ... O13: =(O5-N5)*Assumptions!$B$30
A14: FCFF | B14: =B11+B9-B12-B13 | C14: =C11+C9-C12-C13 | D14: =D11+D9-D12-D13 | E14: =E11+E9-E12-E13 | F14: =F11+F9-F12-F13 | G14: =G11+G9-G12-G13 | H14: =H11+H9-H12-H13 | I14: =I11+I9-I12-I13 | ... O14: =O11+O9-O12-O13

Sheet DCF
A1: Discounted cash flow (USDmm)
A2: Mid-year convention. Terminal value is reinvestment-consistent: TV = NOPATn·(1+g)·(1−g/ROIC)/(WACC−g).
A4: Year | B4: FY2026E | C4: FY2027E | D4: FY2028E | E4: FY2029E | F4: FY2030E | G4: FY2031E | H4: FY2032E | I4: FY2033E | J4: FY2034E | K4: FY2035E
A5: FCFF (from Model) | B5: =Model!F14 | C5: =Model!G14 | D5: =Model!H14 | E5: =Model!I14 | F5: =Model!J14 | G5: =Model!K14 | H5: =Model!L14 | I5: =Model!M14 | ... K5: =Model!O14
A6: Period (mid-year, t−0.5) | B6: 0.5 | C6: 1.5 | D6: 2.5 | E6: 3.5 | F6: 4.5 | G6: 5.5 | H6: 6.5 | I6: 7.5 | J6: 8.5 | K6: 9.5
A7: Discount factor | B7: =1/(1+WACC!$B$10)^B6 | C7: =1/(1+WACC!$B$10)^C6 | D7: =1/(1+WACC!$B$10)^D6 | E7: =1/(1+WACC!$B$10)^E6 | F7: =1/(1+WACC!$B$10)^F6 | G7: =1/(1+WACC!$B$10)^G6 | H7: =1/(1+WACC!$B$10)^H6 | I7: =1/(1+WACC!$B$10)^I6 | ... K7: =1/(1+WACC!$B$10)^K6
A8: PV of FCFF | B8: =B5*B7 | C8: =C5*C7 | D8: =D5*D7 | E8: =E5*E7 | F8: =F5*F7 | G8: =G5*G7 | H8: =H5*H7 | I8: =I5*I7 | ... K8: =K5*K7
A10: PV of explicit FCFF | B10: =SUM(B8:K8)
A11: Terminal NOPAT (FYn) | B11: =Model!O11
A12: Invested capital (mm) | B12: 59136
A13: Terminal invested capital (scaled w/ revenue) | B13: =$B$12*Model!O5/Model!E5
A14: Terminal ROIC | B14: =MAX($B$11/$B$13,WACC!$B$10)
A15: Terminal reinvestment rate (g/ROIC) | B15: =Assumptions!$B$22/$B$14
A16: Terminal value (Gordon) | B16: =$B$11*(1+Assumptions!$B$22)*(1-$B$15)/(WACC!$B$10-Assumptions!$B$22)
A17: PV of terminal value | B17: =$B$16/(1+WACC!$B$10)^(10-0.5)
A18: TV as % of EV | B18: =$B$17/($B$10+$B$17)
A20: Enterprise value | B20: =$B$10+$B$17
A21: (−) Net debt | B21: =-Assumptions!$B$10
A22: (−) Minority interest | B22: =-Assumptions!$B$9
A23: Equity value | B23: =$B$20-Assumptions!$B$10-Assumptions!$B$9
A24: Value per share | B24: =$B$23/Assumptions!$B$6
A25: Upside vs price | B25: =$B$24/Assumptions!$B$5-1

Sheet Sensitivity
A1: Value per share — WACC × terminal growth (USD/share)
A2: Every cell is a live formula; it re-runs the full DCF at that WACC/g pair.
A4: WACC \ g | B4: 0.015 | C4: 0.02 | D4: 0.025 | E4: 0.03 | F4: 0.035
A5: 0.097769669 | B5: =(SUMPRODUCT(DCF!$B$5:$K$5,1/(1+$A$5)^DCF!$B$6:$K$6)+DCF!$B$11*(1+B$4)*(1-B$4/DCF!$B$14)/($A$5-B$4)/(1+$A$5)^(10-0.5)-Assumptions!$B$10-Assumptions!$B$9)/Assumptions!$B$6 | C5: =(SUMPRODUCT(DCF!$B$5:$K$5,1/(1+$A$5)^DCF!$B$6:$K$6)+DCF!$B$11*(1+C$4)*(1-C$4/DCF!$B$14)/($A$5-C$4)/(1+$A$5)^(10-0.5)-Assumptions!$B$10-Assumptions!$B$9)/Assumptions!$B$6 | D5: =(SUMPRODUCT(DCF!$B$5:$K$5,1/(1+$A$5)^DCF!$B$6:$K$6)+DCF!$B$11*(1+D$4)*(1-D$4/DCF!$B$14)/($A$5-D$4)/(1+$A$5)^(10-0.5)-Assumptions!$B$10-Assumptions!$B$9)/Assumptions!$B$6 | E5: =(SUMPRODUCT(DCF!$B$5:$K$5,1/(1+$A$5)^DCF!$B$6:$K$6)+DCF!$B$11*(1+E$4)*(1-E$4/DCF!$B$14)/($A$5-E$4)/(1+$A$5)^(10-0.5)-Assumptions!$B$10-Assumptions!$B$9)/Assumptions!$B$6 | F5: =(SUMPRODUCT(DCF!$B$5:$K$5,1/(1+$A$5)^DCF!$B$6:$K$6)+DCF!$B$11*(1+F$4)*(1-F$4/DCF!$B$14)/($A$5-F$4)/(1+$A$5)^(10-0.5)-Assumptions!$B$10-Assumptions!$B$9)/Assumptions!$B$6
A6: 0.10526967 | B6: =(SUMPRODUCT(DCF!$B$5:$K$5,1/(1+$A$6)^DCF!$B$6:$K$6)+DCF!$B$11*(1+B$4)*(1-B$4/DCF!$B$14)/($A$6-B$4)/(1+$A$6)^(10-0.5)-Assumptions!$B$10-Assumptions!$B$9)/Assumptions!$B$6 | C6: =(SUMPRODUCT(DCF!$B$5:$K$5,1/(1+$A$6)^DCF!$B$6:$K$6)+DCF!$B$11*(1+C$4)*(1-C$4/DCF!$B$14)/($A$6-C$4)/(1+$A$6)^(10-0.5)-Assumptions!$B$10-Assumptions!$B$9)/Assumptions!$B$6 | D6: =(SUMPRODUCT(DCF!$B$5:$K$5,1/(1+$A$6)^DCF!$B$6:$K$6)+DCF!$B$11*(1+D$4)*(1-D$4/DCF!$B$14)/($A$6-D$4)/(1+$A$6)^(10-0.5)-Assumptions!$B$10-Assumptions!$B$9)/Assumptions!$B$6 | E6: =(SUMPRODUCT(DCF!$B$5:$K$5,1/(1+$A$6)^DCF!$B$6:$K$6)+DCF!$B$11*(1+E$4)*(1-E$4/DCF!$B$14)/($A$6-E$4)/(1+$A$6)^(10-0.5)-Assumptions!$B$10-Assumptions!$B$9)/Assumptions!$B$6 | F6: =(SUMPRODUCT(DCF!$B$5:$K$5,1/(1+$A$6)^DCF!$B$6:$K$6)+DCF!$B$11*(1+F$4)*(1-F$4/DCF!$B$14)/($A$6-F$4)/(1+$A$6)^(10-0.5)-Assumptions!$B$10-Assumptions!$B$9)/Assumptions!$B$6
A7: 0.11276967 | B7: =(SUMPRODUCT(DCF!$B$5:$K$5,1/(1+$A$7)^DCF!$B$6:$K$6)+DCF!$B$11*(1+B$4)*(1-B$4/DCF!$B$14)/($A$7-B$4)/(1+$A$7)^(10-0.5)-Assumptions!$B$10-Assumptions!$B$9)/Assumptions!$B$6 | C7: =(SUMPRODUCT(DCF!$B$5:$K$5,1/(1+$A$7)^DCF!$B$6:$K$6)+DCF!$B$11*(1+C$4)*(1-C$4/DCF!$B$14)/($A$7-C$4)/(1+$A$7)^(10-0.5)-Assumptions!$B$10-Assumptions!$B$9)/Assumptions!$B$6 | D7: =(SUMPRODUCT(DCF!$B$5:$K$5,1/(1+$A$7)^DCF!$B$6:$K$6)+DCF!$B$11*(1+D$4)*(1-D$4/DCF!$B$14)/($A$7-D$4)/(1+$A$7)^(10-0.5)-Assumptions!$B$10-Assumptions!$B$9)/Assumptions!$B$6 | E7: =(SUMPRODUCT(DCF!$B$5:$K$5,1/(1+$A$7)^DCF!$B$6:$K$6)+DCF!$B$11*(1+E$4)*(1-E$4/DCF!$B$14)/($A$7-E$4)/(1+$A$7)^(10-0.5)-Assumptions!$B$10-Assumptions!$B$9)/Assumptions!$B$6 | F7: =(SUMPRODUCT(DCF!$B$5:$K$5,1/(1+$A$7)^DCF!$B$6:$K$6)+DCF!$B$11*(1+F$4)*(1-F$4/DCF!$B$14)/($A$7-F$4)/(1+$A$7)^(10-0.5)-Assumptions!$B$10-Assumptions!$B$9)/Assumptions!$B$6
A8: 0.12026967 | B8: =(SUMPRODUCT(DCF!$B$5:$K$5,1/(1+$A$8)^DCF!$B$6:$K$6)+DCF!$B$11*(1+B$4)*(1-B$4/DCF!$B$14)/($A$8-B$4)/(1+$A$8)^(10-0.5)-Assumptions!$B$10-Assumptions!$B$9)/Assumptions!$B$6 | C8: =(SUMPRODUCT(DCF!$B$5:$K$5,1/(1+$A$8)^DCF!$B$6:$K$6)+DCF!$B$11*(1+C$4)*(1-C$4/DCF!$B$14)/($A$8-C$4)/(1+$A$8)^(10-0.5)-Assumptions!$B$10-Assumptions!$B$9)/Assumptions!$B$6 | D8: =(SUMPRODUCT(DCF!$B$5:$K$5,1/(1+$A$8)^DCF!$B$6:$K$6)+DCF!$B$11*(1+D$4)*(1-D$4/DCF!$B$14)/($A$8-D$4)/(1+$A$8)^(10-0.5)-Assumptions!$B$10-Assumptions!$B$9)/Assumptions!$B$6 | E8: =(SUMPRODUCT(DCF!$B$5:$K$5,1/(1+$A$8)^DCF!$B$6:$K$6)+DCF!$B$11*(1+E$4)*(1-E$4/DCF!$B$14)/($A$8-E$4)/(1+$A$8)^(10-0.5)-Assumptions!$B$10-Assumptions!$B$9)/Assumptions!$B$6 | F8: =(SUMPRODUCT(DCF!$B$5:$K$5,1/(1+$A$8)^DCF!$B$6:$K$6)+DCF!$B$11*(1+F$4)*(1-F$4/DCF!$B$14)/($A$8-F$4)/(1+$A$8)^(10-0.5)-Assumptions!$B$10-Assumptions!$B$9)/Assumptions!$B$6
A9: 0.12776967 | B9: =(SUMPRODUCT(DCF!$B$5:$K$5,1/(1+$A$9)^DCF!$B$6:$K$6)+DCF!$B$11*(1+B$4)*(1-B$4/DCF!$B$14)/($A$9-B$4)/(1+$A$9)^(10-0.5)-Assumptions!$B$10-Assumptions!$B$9)/Assumptions!$B$6 | C9: =(SUMPRODUCT(DCF!$B$5:$K$5,1/(1+$A$9)^DCF!$B$6:$K$6)+DCF!$B$11*(1+C$4)*(1-C$4/DCF!$B$14)/($A$9-C$4)/(1+$A$9)^(10-0.5)-Assumptions!$B$10-Assumptions!$B$9)/Assumptions!$B$6 | D9: =(SUMPRODUCT(DCF!$B$5:$K$5,1/(1+$A$9)^DCF!$B$6:$K$6)+DCF!$B$11*(1+D$4)*(1-D$4/DCF!$B$14)/($A$9-D$4)/(1+$A$9)^(10-0.5)-Assumptions!$B$10-Assumptions!$B$9)/Assumptions!$B$6 | E9: =(SUMPRODUCT(DCF!$B$5:$K$5,1/(1+$A$9)^DCF!$B$6:$K$6)+DCF!$B$11*(1+E$4)*(1-E$4/DCF!$B$14)/($A$9-E$4)/(1+$A$9)^(10-0.5)-Assumptions!$B$10-Assumptions!$B$9)/Assumptions!$B$6 | F9: =(SUMPRODUCT(DCF!$B$5:$K$5,1/(1+$A$9)^DCF!$B$6:$K$6)+DCF!$B$11*(1+F$4)*(1-F$4/DCF!$B$14)/($A$9-F$4)/(1+$A$9)^(10-0.5)-Assumptions!$B$10-Assumptions!$B$9)/Assumptions!$B$6

Sheet IS (reported)
A1: MU — IS (reported)
A2: As reported by Yahoo snapshot as of 2026-07-09 (USDmm). Hardcoded actuals.
A4: Line item | B4: FY2021 | C4: FY2022 | D4: FY2023 | E4: FY2024 | F4: FY2025
A5: Tax Effect Of Unusual Items | C5: -5.952 | D5: -69.3 | E5: -5.46 | F5: -19.72
A6: Tax Rate For Calcs | C6: 9.3e-14 | D6: 2.1e-13 | E6: 3.64e-13 | F6: 1.16e-13
A7: Normalized EBITDA | C7: 16940 | D7: 2816 | E7: 9597 | F7: 18653
A8: Total Unusual Items | C8: -64 | D8: -330 | E8: -15 | F8: -170
A9: Total Unusual Items Excluding Goodwill | C9: -64 | D9: -330 | E9: -15 | F9: -170
A10: Net Income From Continuing Operation Net Minority Interest | C10: 8687 | D10: -5833 | E10: 778 | F10: 8539
A11: Reconciled Depreciation | C11: 7116 | D11: 7756 | E11: 7780 | F11: 8352
A12: Reconciled Cost Of Revenue | C12: 16860 | D12: 16956 | E12: 19498 | F12: 22505
A13: EBITDA | C13: 16876 | D13: 2486 | E13: 9582 | F13: 18483
A14: EBIT | C14: 9760 | D14: -5270 | E14: 1802 | F14: 10131
A15: Net Interest Income | C15: -93 | D15: 80 | E15: -33 | F15: 19
A16: Interest Expense | C16: 189 | D16: 388 | E16: 562 | F16: 477
... A26: Diluted NI Availto Com Stockholders | C26: 8687 | D26: -5833 | E26: 778 | F26: 8539
A27: Average Dilution Earnings | B27: 0 | C27: 0
A28: Net Income Common Stockholders | C28: 8687 | D28: -5833 | E28: 778 | F28: 8539
A29: Net Income | C29: 8687 | D29: -5833 | E29: 778 | F29: 8539
A30: Minority Interests | B30: 0 | C30: 0
A31: Net Income Including Noncontrolling Interests | C31: 8687 | D31: -5833 | E31: 778 | F31: 8539
A32: Net Income Continuous Operations | C32: 8687 | D32: -5833 | E32: 778 | F32: 8539
A33: Earnings From Equity Interest Net Of Tax | C33: 4 | D33: 2 | E33: -11 | F33: 9
A34: Tax Provision | C34: 888 | D34: 177 | E34: 451 | F34: 1124
A35: Pretax Income | C35: 9571 | D35: -5658 | E35: 1240 | F35: 9654
A36: Other Income Expense | C36: -45 | D36: -333 | E36: -32 | F36: -174
A37: Other Non Operating Income Expenses | C37: 19 | D37: -3 | E37: -17 | F37: -4
A38: Special Income Charges | C38: -90 | D38: -340 | E38: -2 | F38: -98
A39: Gain On Sale Of Ppe | B39: 24 | C39: 41 | D39: 54 | E39: 59
A40: Other Special Charges | B40: 1 | C40: 83 | D40: 68 | F40: 59
A41: Write Off | C41: 63 | D41: 14 | E41: 0 | F41: 9
A42: Impairment Of Capital Assets | C42: 0 | D42: 101 | E42: 0 | F42: 0
A43: Restructuring And Mergern Acquisition | C43: -15 | D43: 157 | E43: 1 | F43: 30
A44: Gain On Sale Of Security | B44: 82 | C44: 26 | D44: 10 | F44: -72
A45: Net Non Operating Interest Income Expense | C45: -93 | D45: 80 | E45: -33 | F45: 19
A46: Interest Expense Non Operating | C46: 189 | D46: 388 | E46: 562 | F46: 477
A47: Interest Income Non Operating | C47: 96 | D47: 468 | E47: 529 | F47: 496
A48: Operating Income | C48: 9709 | D48: -5405 | E48: 1305 | F48: 9809
A49: Operating Expense | C49: 4189 | D49: 3989 | E49: 4308 | F49: 5064
A50: Other Operating Expenses | C50: 7 | D50: -45 | E50: -251 | F50: 61
...

Sheet BS (reported)
A1: MU — BS (reported)
A2: As reported by Yahoo snapshot as of 2026-07-09 (USDmm). Hardcoded actuals.
A4: Line item | B4: FY2021 | C4: FY2022 | D4: FY2023 | E4: FY2024 | F4: FY2025
A5: Treasury Shares Number | C5: 132 | D5: 141 | E5: 144 | F5: 144
A6: Ordinary Shares Number | C6: 1094 | D6: 1098 | E6: 1108.8413 | F6: 1122
A7: Share Issued | C7: 1226 | D7: 1239 | E7: 1252.8413 | F7: 1266
A8: Net Debt | D8: 3472 | E8: 4302 | F8: 1891
A9: Total Debt | C9: 7516 | D9: 13933 | E9: 14007 | F9: 15278
A10: Tangible Book Value | C10: 48258 | D10: 42566 | E10: 43565 | F10: 52562
A11: Invested Capital | C11: 55927 | D11: 56169 | E11: 56474 | F11: 65698
A12: Working Capital | C12: 14242 | D12: 16479 | E12: 15124 | F12: 17387
A13: Net Tangible Assets | C13: 48258 | D13: 42566 | E13: 43565 | F13: 52562
A14: Capital Lease Obligations | C14: 1496 | D14: 1884 | E14: 2664 | F14: 3745
A15: Common Stock Equity | C15: 49907 | D15: 44120 | E15: 45131 | F15: 54165
A16: Total Capitalization | C16: 55927 | D16: 56063 | E16: 56368 | F16: 65698
A17: Total Equity Gross Minority Interest | C17: 49907 | D17: 44120 | E17: 45131 | F17: 54165
A18: Stockholders Equity | C18: 49907 | D18: 44120 | E18: 45131 | F18: 54165
A19: Gains Losses Not Affecting Retained Earnings | C19: -560 | D19: -312 | E19: -134 | F19: -32
A20: Other Equity Adjustments | C20: -560 | D20: -312 | E20: -134 | F20: -32
... A37: Current Capital Lease Obligation | C37: 103 | D37: 172 | E37: 325 | F37: 560
A38: Current Debt | B38: 1 | D38: 106 | E38: 106
A39: Other Current Borrowings | B39: 1 | D39: 106 | E39: 106
A40: Current Notes Payable | B40: 0
A41: Payables And Accrued Expenses | C41: 6090 | D41: 3958 | E41: 7299 | F41: 9649
A42: Current Accrued Expenses | C42: 1358 | D42: 747 | E42: 1430 | F42: 1498
A43: Payables | C43: 4732 | D43: 3211 | E43: 5869 | F43: 8151
A44: Other Payable | C44: 2170 | D44: 1419 | E44: 2925 | F44: 4391
A45: Total Tax Payable | C45: 420 | D45: 67 | E45: 218 | F45: 628
A46: Accounts Payable | C46: 2142 | D46: 1725 | E46: 2726 | F46: 3132
A47: Total Assets | C47: 66283 | D47: 64254 | E47: 69416 | F47: 82798
A48: Total Non Current Assets | C48: 44502 | D48: 43010 | E48: 45044 | F48: 53957
A49: Other Non Current Assets | C49: 1277 | D49: 1262 | E49: 1518 | F49: 2783
A50: Non Current Deferred Assets | C50: 702 | D50: 756 | E50: 520 | F50: 616
A51: Non Current Deferred Taxes Assets | C51: 702 | D51: 756 | E51: 520 | F51: 616
A52: Investments And Advances | C52: 1647 | D52: 844 | E52: 1046 | F52: 1629
... A68: Other Current Assets | C68: 657 | D68: 820 | E68: 776 | F68: 914
A69: Assets Held For Sale Current | B69: 974 | C69: 13
A70: Inventory | C70: 6663 | D70: 8387 | E70: 8875 | F70: 8355
A71: Finished Goods | C71: 1028 | D71: 1616 | E71: 1308 | F71: 1094
A72: Work In Process | C72: 4830 | D72: 6111 | E72: 6774 | F72: 6401
...

Sheet CF (reported)
A1: MU — CF (reported)
A2: As reported by Yahoo snapshot as of 2026-07-09 (USDmm). Hardcoded actuals.
A4: Line item | B4: FY2021 | C4: FY2022 | D4: FY2023 | E4: FY2024 | F4: FY2025
A5: Free Cash Flow | C5: 3114 | D5: -6117 | E5: 121 | F5: 1668
A6: Repurchase Of Capital Stock | C6: -2432 | D6: -425 | E6: -300 | F6: 0
A7: Repayment Of Debt | C7: -2032 | D7: -761 | E7: -1897 | F7: -4619
A8: Issuance Of Debt | C8: 2000 | D8: 6716 | E8: 999 | F8: 4430
A9: Capital Expenditure | C9: -12067 | D9: -7676 | E9: -8386 | F9: -15857
A10: Interest Paid Supplemental Data | C10: 154 | D10: 323 | E10: 503 | F10: 418
A11: Income Tax Paid Supplemental Data | C11: 493 | D11: 532 | E11: 338 | F11: 583
A12: End Cash Position | C12: 8339 | D12: 8656 | E12: 7052 | F12: 9646
A13: Beginning Cash Position | C13: 7829 | D13: 8339 | E13: 8656 | F13: 7052
A14: Effect Of Exchange Rate Changes | C14: -106 | D14: -34 | E14: 40 | F14: 6
A15: Changes In Cash | C15: 616 | D15: 351 | E15: -1644 | F15: 2588
A16: Financing Cash Flow | C16: -2980 | D16: 4983 | E16: -1842 | F16: -850
... A18: Net Other Financing Charges | C18: -55 | D18: -43 | E18: -131 | F18: -139
A19: Proceeds From Stock Option Exercised | B19: -94 | C19: -125
A20: Cash Dividends Paid | C20: -461 | D20: -504 | E20: -513 | F20: -522
A21: Common Stock Dividend Paid | C21: -461 | D21: -504 | E21: -513 | F21: -522
A22: Net Common Stock Issuance | C22: -2432 | D22: -425 | E22: -300 | F22: 0
A23: Common Stock Payments | C23: -2432 | D23: -425 | E23: -300 | F23: 0
A24: Net Issuance Payments Of Debt | C24: -32 | D24: 5955 | E24: -898 | F24: -189
A25: Net Long Term Debt Issuance | C25: -32 | D25: 5955 | E25: -898 | F25: -189
A26: Long Term Debt Payments | C26: -2032 | D26: -761 | E26: -1897 | F26: -4619
A27: Long Term Debt Issuance | C27: 2000 | D27: 6716 | E27: 999 | F27: 4430
A28: Investing Cash Flow | C28: -11585 | D28: -6191 | E28: -8309 | F28: -14087
A29: Cash Flow From Continuing Investing Activities | C29: -11585 | D29: -6191 | E29: -8309 | F29: -14087
A30: Net Other Investing Changes | C30: -251 | D30: 617 | E30: 282 | F30: 1962
A31: Net Investment Purchase And Sale | C31: -155 | D31: 868 | E31: -205 | F31: -192
... A33: Purchase Of Investment | C33: -1770 | D33: -723 | E33: -1999 | F33: -1890
A34: Net Business Purchase And Sale | B34: 0 | C34: 888 | D34: 0 | E34: 0
A35: Sale Of Business | B35: 0 | C35: 888 | D35: 0 | E35: 0
A36: Capital Expenditure Reported | C36: -12067 | D36: -7676 | E36: -8386 | F36: -15857
A37: Operating Cash Flow | C37: 15181 | D37: 1559 | E37: 8507 | F37: 17525
A38: Cash Flow From Continuing Operating Activities | C38: 15181 | D38: 1559 | E38: 8507 | F38: 17525
A39: Change In Working Capital | C39: -1255 | D39: -2911 | E39: -1165 | F39: -666
A40: Change In Other Working Capital | B40: -50
A41: Change In Other Current Liabilities | C41: 400 | D41: -817 | E41: 989 | F41: -272
A42: Change In Payables And Accrued Expense | C42: 334 | D42: -1302 | E42: 1915 | F42: 862
A43: Change In Inventory | C43: -2179 | D43: -3555 | E43: -488 | F43: 520
...
