Workbook

Sheet Cover
A1: RTX Corporation (RTX)
A2: Industrials · Standard (forward multiples + DCF) · generated 2026-10-13 · data: yfinance
A4: Current price | B4: =Assumptions!$B$5
A5: DCF value per share (one lens) | B5: =DCF!$B$24
A6: Upside / downside | B6: =DCF!$B$24/Assumptions!$B$5-1
A7: 12-month price target (report) | B7: 183.68882
A8: WACC | B8: =WACC!$B$10
A10: How to use
A11: Blue cells are inputs — edit growth, margins, beta, ERP or terminal g
A12: in the Assumptions sheet and everything recalculates live.
A13: Black cells are formulas; green cells link across sheets.
A14: The Sensitivity grid re-runs the full DCF per WACC/g pair.
A15: Not investment advice. Verify source data before relying on outputs.

Sheet Target Price
A1: RTX — 12-month price target (lens triangulation)
A2: Blue = inputs (weights, Ke, dividends, Street weight); black = live formulas. Change a weight and the blended fair value and target recalculate. Guardrail exclusions are already reflected in the effective weights.
A4: Lens | B4: Type | C4: Value / share | D4: Low | E4: High | F4: Weight | G4: Status
A5: Discounted cash flow (FCFF) | B5: intrinsic | C5: 121.48012 | D5: 85.50478 | E5: 165.59031 | F5: 0.37234043 | G5: ok
A6: Forward P/E | B6: relative | C6: 175.23081 | D6: 143.68927 | E6: 206.77236 | F6: 0.31914894 | G6: ok
A7: Forward EV/EBITDA | B7: relative | C7: 191.01782 | D7: 152.09854 | E7: 229.93709 | F7: 0.26595745 | G7: ok
A8: Multi-stage dividend discount | B8: sector | C8: 55.828421 | D8: 44.662737 | E8: 66.994105 | F8: 0.042553191 | G8: ok — down-weighted: 0.4x the median of the other lenses
A10: Weights sum | B10: =SUM(F5:F8)
A11: Blended fair value (today) | B11: =SUMPRODUCT(C5:C8,F5:F8)/SUM(F5:F8)
A12: Cost of equity (Ke) | B12: 0.080152296
A13: Dividends per share (12m) | B13: 2.92
A14: Model 12-month target = FV×(1+Ke)−DPS | B14: =$B$11*(1+$B$12)-$B$13
A15: Street mean target | B15: 230.13043
A16: Street weight in target | B16: 0.3
A17: Published 12-month target | B17: =(1-$B$16)*$B$14+$B$16*$B$15
A18: Current price | B18: 181.9101
A19: Engine target (incl. plausibility band) | B19: 183.68882
A21: Guardrails
A22: Multi-stage dividend discount sits 0.4x the lens median and was down-weighted by 60%.
A23: Target anchored 30% to the Street consensus ($230.13, 23 analysts); model-only target $163.79.

Sheet Financial Model
A1: RTX — projected P&L & levered FCF (DCF base case)
A2: Blue = consensus-sourced figures; black = live formulas. Revenue and EBIT margin are the DCF base-case drivers; levered FCF = unlevered FCF less after-tax interest.
A4: Line item | B4: FY2026E | C4: FY2027E | D4: FY2028E | E4: FY2029E | F4: FY2030E | G4: FY2031E | H4: FY2032E | I4: FY2033E | J4: FY2034E | K4: FY2035E
A5: Revenue (mn) | B5: 96167.91 | C5: 103405.58 | D5: 109564.64 | E5: 114907.77 | F5: 119658.45 | G5: 123994.71 | H5: 128052.85 | I5: 131934.7 | J5: 135715.22 | K5: 139108.1
A6: Revenue growth | B6: — | C6: =C5/B5-1 | D6: =D5/C5-1 | E6: =E5/D5-1 | F6: =F5/E5-1 | G6: =G5/F5-1 | H6: =H5/G5-1 | I6: =I5/H5-1 | J6: =J5/I5-1 | K6: =K5/J5-1
A7: EBIT margin | B7: 0.13964813 | C7: 0.13941254 | D7: 0.13643776 | E7: 0.13346298 | F7: 0.1304882 | G7: 0.12751342 | H7: 0.12453864 | I7: 0.12156386 | J7: 0.12156386 | K7: 0.12156386
A8: EBIT (mn) | B8: =B5*B7 | C8: =C5*C7 | D8: =D5*D7 | E8: =E5*E7 | F8: =F5*F7 | G8: =G5*G7 | H8: =H5*H7 | I8: =I5*I7 | ... K8: =K5*K7
A9: Net income (mn) | B9: 9770.7344 | C9: 10601.937 | D9: 11050.856 | E9: 11377.128 | F9: 11611.466 | G9: 11777.454 | H9: 11892.514 | I9: 11969.168 | J9: 12356.448 | K9: 12704.018
A10: EPS | B10: =B9*1000000/1347758144.0 | C10: =C9*1000000/1347758144.0 | D10: =D9*1000000/1347758144.0 | E10: =E9*1000000/1347758144.0 | F10: =F9*1000000/1347758144.0 | G10: =G9*1000000/1347758144.0 | H10: =H9*1000000/1347758144.0 | I10: =I9*1000000/1347758144.0 | ... K10: =K9*1000000/1347758144.0
A12: Levered FCF (mn) | B12: 10330.629 | C12: 11071.299 | D12: 11478.628 | E12: 11693.56 | F12: 11759.013 | G12: 11709.271 | H12: 11570.217 | I12: 11360.647 | J12: 11434.018 | K12: 11488.18
A13: FCF margin | B13: =B12/B5 | C13: =C12/C5 | D13: =D12/D5 | E13: =E12/E5 | F13: =F12/F5 | G13: =G12/G5 | H13: =H12/H5 | I13: =I12/I5 | ... K13: =K12/K5
A15: → Unlevered FCF (before interest) is what the 'DCF' sheet discounts.

Sheet Assumptions
A1: RTX — Assumptions & Drivers
A2: Blue cells are inputs — change them and the whole model recalculates. Source: yfinance, retrieved 2026-10-13.
A4: Market data
A5: Share price (USD) | B5: 181.9101
A6: Diluted shares (mn) | B6: 1347.7581
A7: Total debt (USDmm) | B7: 39506
A8: Cash & ST investments (USDmm) | B8: 7435
A9: Minority interest (USDmm) | B9: 1893
A10: Net debt (USDmm) | B10: =Assumptions!$B$7-Assumptions!$B$8
A12: Cost of capital inputs
A13: Risk-free rate (Rf) | B13: 0.043
A14: Equity risk premium (ERP) | B14: 0.046
A15: Country risk premium | B15: 0
A16: Size premium | B16: 0
A17: Beta (levered) | B17: 0.81
A18: Pre-tax cost of debt | B18: 0.055
A19: Tax rate | B19: 0.15730803
A21: Terminal assumptions
A22: Terminal growth (g) | B22: 0.025
A24: Per-year forecast drivers
A25: Driver | B25: FY2026E | C25: FY2027E | D25: FY2028E | E25: FY2029E | F25: FY2030E | G25: FY2031E | H25: FY2032E | I25: FY2033E | J25: FY2034E | K25: FY2035E
A26: Revenue growth | B26: 0.085379844 | C26: 0.075260806 | D26: 0.059562146 | E26: 0.048766868 | F26: 0.04134343 | G26: 0.036238658 | H26: 0.032728331 | I26: 0.030314433 | J26: 0.028654502 | K26: 0.025
A27: EBIT margin | B27: 0.13964813 | C27: 0.13941254 | D27: 0.13643776 | E27: 0.13346298 | F27: 0.1304882 | G27: 0.12751342 | H27: 0.12453864 | I27: 0.12156386 | J27: 0.12156386 | K27: 0.12156386
A28: D&A % of revenue | B28: 0.056452102 | C28: 0.056452102 | D28: 0.056452102 | E28: 0.056452102 | F28: 0.056452102 | G28: 0.056452102 | H28: 0.056452102 | I28: 0.056452102 | J28: 0.056452102 | K28: 0.056452102
A29: Capex % of revenue | B29: 0.040647941 | C29: 0.043031204 | D29: 0.045414468 | E29: 0.047797731 | F29: 0.050180995 | G29: 0.052564258 | H29: 0.054947522 | I29: 0.057330786 | J29: 0.059714049 | K29: 0.062097313
A30: ΔNWC % of Δrevenue | B30: 0.12689629

Sheet WACC
A1: Cost of capital (CAPM)
A2: All formulas reference the Assumptions sheet.
A4: Cost of equity (Ke = Rf + β·ERP + CRP + size) | B4: =Assumptions!$B$13+Assumptions!$B$17*Assumptions!$B$14+Assumptions!$B$15+Assumptions!$B$16
A5: After-tax cost of debt (Kd·(1−t)) | B5: =Assumptions!$B$18*(1-Assumptions!$B$19)
A6: Market value of equity (mm) | B6: =Assumptions!$B$5*Assumptions!$B$6
A7: Debt (book, mm) | B7: =Assumptions!$B$7
A8: Weight of equity | B8: =WACC!$B$6/(WACC!$B$6+WACC!$B$7)
A9: Weight of debt | B9: =1-WACC!$B$8
A10: WACC | B10: =WACC!$B$8*WACC!$B$4+WACC!$B$9*WACC!$B$5

Sheet Model
A1: Operating model (USDmm)
A2: Shaded columns are reported actuals (blue hardcodes, sourced); unshaded are forecast formulas driven by the Assumptions sheet.
A4: Line item | B4: FY2022A | C4: FY2023A | D4: FY2024A | E4: FY2025A | F4: FY2026E | G4: FY2027E | H4: FY2028E | I4: FY2029E | J4: FY2030E | K4: FY2031E | L4: FY2032E | M4: FY2033E | N4: FY2034E | O4: FY2035E
A5: Revenue | B5: 67074 | C5: 68920 | D5: 80738 | E5: 88603 | F5: =E5*(1+Assumptions!B$26) | G5: =F5*(1+Assumptions!C$26) | H5: =G5*(1+Assumptions!D$26) | I5: =H5*(1+Assumptions!E$26) | J5: =I5*(1+Assumptions!F$26) | K5: =J5*(1+Assumptions!G$26) | L5: =K5*(1+Assumptions!H$26) | M5: =L5*(1+Assumptions!I$26) | ... O5: =N5*(1+Assumptions!K$26)
A6: growth % | C6: =C5/B5-1 | D6: =D5/C5-1 | E6: =E5/D5-1 | F6: =F5/E5-1 | G6: =G5/F5-1 | H6: =H5/G5-1 | I6: =I5/H5-1 | J6: =J5/I5-1 | ... O6: =O5/N5-1
A7: EBIT | B7: 5504 | C7: 3561 | D7: 6538 | E7: 9300 | F7: =F5*Assumptions!B$27 | G7: =G5*Assumptions!C$27 | H7: =H5*Assumptions!D$27 | I7: =I5*Assumptions!E$27 | J7: =J5*Assumptions!F$27 | K7: =K5*Assumptions!G$27 | L7: =L5*Assumptions!H$27 | M7: =M5*Assumptions!I$27 | ... O7: =O5*Assumptions!K$27
A8: EBIT margin % | B8: =B7/B5 | C8: =C7/C5 | D8: =D7/D5 | E8: =E7/E5 | F8: =F7/F5 | G8: =G7/G5 | H8: =H7/H5 | I8: =I7/I5 | ... O8: =O7/O5
A9: D&A | B9: 4108 | C9: 4211 | D9: 4364 | E9: 4378 | F9: =F5*Assumptions!B$28 | G9: =G5*Assumptions!C$28 | H9: =H5*Assumptions!D$28 | I9: =I5*Assumptions!E$28 | J9: =J5*Assumptions!F$28 | K9: =K5*Assumptions!G$28 | L9: =L5*Assumptions!H$28 | M9: =M5*Assumptions!I$28 | ... O9: =O5*Assumptions!K$28
A10: EBITDA | B10: =B7+B9 | C10: =C7+C9 | D10: =D7+D9 | E10: =E7+E9 | F10: =F7+F9 | G10: =G7+G9 | H10: =H7+H9 | I10: =I7+I9 | ... O10: =O7+O9
A11: NOPAT (EBIT×(1−t)) | B11: =B7*(1-Assumptions!$B$19) | C11: =C7*(1-Assumptions!$B$19) | D11: =D7*(1-Assumptions!$B$19) | E11: =E7*(1-Assumptions!$B$19) | F11: =F7*(1-Assumptions!$B$19) | G11: =G7*(1-Assumptions!$B$19) | H11: =H7*(1-Assumptions!$B$19) | I11: =I7*(1-Assumptions!$B$19) | ... O11: =O7*(1-Assumptions!$B$19)
A12: Capex | B12: 2775 | C12: 3166 | D12: 3236 | E12: 3119 | F12: =F5*Assumptions!B$29 | G12: =G5*Assumptions!C$29 | H12: =H5*Assumptions!D$29 | I12: =I5*Assumptions!E$29 | J12: =J5*Assumptions!F$29 | K12: =K5*Assumptions!G$29 | L12: =L5*Assumptions!H$29 | M12: =M5*Assumptions!I$29 | ... O12: =O5*Assumptions!K$29
A13: Δ Net working capital | B13: -522 | C13: -1515 | D13: 1085 | E13: 1274 | F13: =(F5-E5)*Assumptions!$B$30 | G13: =(G5-F5)*Assumptions!$B$30 | H13: =(H5-G5)*Assumptions!$B$30 | I13: =(I5-H5)*Assumptions!$B$30 | J13: =(J5-I5)*Assumptions!$B$30 | K13: =(K5-J5)*Assumptions!$B$30 | L13: =(L5-K5)*Assumptions!$B$30 | M13: =(M5-L5)*Assumptions!$B$30 | ... O13: =(O5-N5)*Assumptions!$B$30
A14: FCFF | B14: =B11+B9-B12-B13 | C14: =C11+C9-C12-C13 | D14: =D11+D9-D12-D13 | E14: =E11+E9-E12-E13 | F14: =F11+F9-F12-F13 | G14: =G11+G9-G12-G13 | H14: =H11+H9-H12-H13 | I14: =I11+I9-I12-I13 | ... O14: =O11+O9-O12-O13

Sheet DCF
A1: Discounted cash flow (USDmm)
A2: Mid-year convention. Terminal value is reinvestment-consistent: TV = NOPATn·(1+g)·(1−g/ROIC)/(WACC−g).
A4: Year | B4: FY2026E | C4: FY2027E | D4: FY2028E | E4: FY2029E | F4: FY2030E | G4: FY2031E | H4: FY2032E | I4: FY2033E | J4: FY2034E | K4: FY2035E
A5: FCFF (from Model) | B5: =Model!F14 | C5: =Model!G14 | D5: =Model!H14 | E5: =Model!I14 | F5: =Model!J14 | G5: =Model!K14 | H5: =Model!L14 | I5: =Model!M14 | ... K5: =Model!O14
A6: Period (mid-year, t−0.5) | B6: 0.5 | C6: 1.5 | D6: 2.5 | E6: 3.5 | F6: 4.5 | G6: 5.5 | H6: 6.5 | I6: 7.5 | J6: 8.5 | K6: 9.5
A7: Discount factor | B7: =1/(1+WACC!$B$10)^B6 | C7: =1/(1+WACC!$B$10)^C6 | D7: =1/(1+WACC!$B$10)^D6 | E7: =1/(1+WACC!$B$10)^E6 | F7: =1/(1+WACC!$B$10)^F6 | G7: =1/(1+WACC!$B$10)^G6 | H7: =1/(1+WACC!$B$10)^H6 | I7: =1/(1+WACC!$B$10)^I6 | ... K7: =1/(1+WACC!$B$10)^K6
A8: PV of FCFF | B8: =B5*B7 | C8: =C5*C7 | D8: =D5*D7 | E8: =E5*E7 | F8: =F5*F7 | G8: =G5*G7 | H8: =H5*H7 | I8: =I5*I7 | ... K8: =K5*K7
A10: PV of explicit FCFF | B10: =SUM(B8:K8)
A11: Terminal NOPAT (FYn) | B11: =Model!O11
A12: Invested capital (mm) | B12: 97316
A13: Terminal invested capital (scaled w/ revenue) | B13: =$B$12*Model!O5/Model!E5
A14: Terminal ROIC | B14: =MAX($B$11/$B$13,WACC!$B$10)
A15: Terminal reinvestment rate (g/ROIC) | B15: =Assumptions!$B$22/$B$14
A16: Terminal value (Gordon) | B16: =$B$11*(1+Assumptions!$B$22)*(1-$B$15)/(WACC!$B$10-Assumptions!$B$22)
A17: PV of terminal value | B17: =$B$16/(1+WACC!$B$10)^(10-0.5)
A18: TV as % of EV | B18: =$B$17/($B$10+$B$17)
A20: Enterprise value | B20: =$B$10+$B$17
A21: (−) Net debt | B21: =-Assumptions!$B$10
A22: (−) Minority interest | B22: =-Assumptions!$B$9
A23: Equity value | B23: =$B$20-Assumptions!$B$10-Assumptions!$B$9
A24: Value per share | B24: =$B$23/Assumptions!$B$6
A25: Upside vs price | B25: =$B$24/Assumptions!$B$5-1

Sheet Sensitivity
A1: Value per share — WACC × terminal growth (USD/share)
A2: Every cell is a live formula; it re-runs the full DCF at that WACC/g pair.
A4: WACC \ g | B4: 0.015 | C4: 0.02 | D4: 0.025 | E4: 0.03 | F4: 0.035
A5: 0.060462428 | B5: =(SUMPRODUCT(DCF!$B$5:$K$5,1/(1+$A$5)^DCF!$B$6:$K$6)+DCF!$B$11*(1+B$4)*(1-B$4/DCF!$B$14)/($A$5-B$4)/(1+$A$5)^(10-0.5)-Assumptions!$B$10-Assumptions!$B$9)/Assumptions!$B$6 | C5: =(SUMPRODUCT(DCF!$B$5:$K$5,1/(1+$A$5)^DCF!$B$6:$K$6)+DCF!$B$11*(1+C$4)*(1-C$4/DCF!$B$14)/($A$5-C$4)/(1+$A$5)^(10-0.5)-Assumptions!$B$10-Assumptions!$B$9)/Assumptions!$B$6 | D5: =(SUMPRODUCT(DCF!$B$5:$K$5,1/(1+$A$5)^DCF!$B$6:$K$6)+DCF!$B$11*(1+D$4)*(1-D$4/DCF!$B$14)/($A$5-D$4)/(1+$A$5)^(10-0.5)-Assumptions!$B$10-Assumptions!$B$9)/Assumptions!$B$6 | E5: =(SUMPRODUCT(DCF!$B$5:$K$5,1/(1+$A$5)^DCF!$B$6:$K$6)+DCF!$B$11*(1+E$4)*(1-E$4/DCF!$B$14)/($A$5-E$4)/(1+$A$5)^(10-0.5)-Assumptions!$B$10-Assumptions!$B$9)/Assumptions!$B$6 | F5: =(SUMPRODUCT(DCF!$B$5:$K$5,1/(1+$A$5)^DCF!$B$6:$K$6)+DCF!$B$11*(1+F$4)*(1-F$4/DCF!$B$14)/($A$5-F$4)/(1+$A$5)^(10-0.5)-Assumptions!$B$10-Assumptions!$B$9)/Assumptions!$B$6
A6: 0.067962428 | B6: =(SUMPRODUCT(DCF!$B$5:$K$5,1/(1+$A$6)^DCF!$B$6:$K$6)+DCF!$B$11*(1+B$4)*(1-B$4/DCF!$B$14)/($A$6-B$4)/(1+$A$6)^(10-0.5)-Assumptions!$B$10-Assumptions!$B$9)/Assumptions!$B$6 | C6: =(SUMPRODUCT(DCF!$B$5:$K$5,1/(1+$A$6)^DCF!$B$6:$K$6)+DCF!$B$11*(1+C$4)*(1-C$4/DCF!$B$14)/($A$6-C$4)/(1+$A$6)^(10-0.5)-Assumptions!$B$10-Assumptions!$B$9)/Assumptions!$B$6 | D6: =(SUMPRODUCT(DCF!$B$5:$K$5,1/(1+$A$6)^DCF!$B$6:$K$6)+DCF!$B$11*(1+D$4)*(1-D$4/DCF!$B$14)/($A$6-D$4)/(1+$A$6)^(10-0.5)-Assumptions!$B$10-Assumptions!$B$9)/Assumptions!$B$6 | E6: =(SUMPRODUCT(DCF!$B$5:$K$5,1/(1+$A$6)^DCF!$B$6:$K$6)+DCF!$B$11*(1+E$4)*(1-E$4/DCF!$B$14)/($A$6-E$4)/(1+$A$6)^(10-0.5)-Assumptions!$B$10-Assumptions!$B$9)/Assumptions!$B$6 | F6: =(SUMPRODUCT(DCF!$B$5:$K$5,1/(1+$A$6)^DCF!$B$6:$K$6)+DCF!$B$11*(1+F$4)*(1-F$4/DCF!$B$14)/($A$6-F$4)/(1+$A$6)^(10-0.5)-Assumptions!$B$10-Assumptions!$B$9)/Assumptions!$B$6
A7: 0.075462428 | B7: =(SUMPRODUCT(DCF!$B$5:$K$5,1/(1+$A$7)^DCF!$B$6:$K$6)+DCF!$B$11*(1+B$4)*(1-B$4/DCF!$B$14)/($A$7-B$4)/(1+$A$7)^(10-0.5)-Assumptions!$B$10-Assumptions!$B$9)/Assumptions!$B$6 | C7: =(SUMPRODUCT(DCF!$B$5:$K$5,1/(1+$A$7)^DCF!$B$6:$K$6)+DCF!$B$11*(1+C$4)*(1-C$4/DCF!$B$14)/($A$7-C$4)/(1+$A$7)^(10-0.5)-Assumptions!$B$10-Assumptions!$B$9)/Assumptions!$B$6 | D7: =(SUMPRODUCT(DCF!$B$5:$K$5,1/(1+$A$7)^DCF!$B$6:$K$6)+DCF!$B$11*(1+D$4)*(1-D$4/DCF!$B$14)/($A$7-D$4)/(1+$A$7)^(10-0.5)-Assumptions!$B$10-Assumptions!$B$9)/Assumptions!$B$6 | E7: =(SUMPRODUCT(DCF!$B$5:$K$5,1/(1+$A$7)^DCF!$B$6:$K$6)+DCF!$B$11*(1+E$4)*(1-E$4/DCF!$B$14)/($A$7-E$4)/(1+$A$7)^(10-0.5)-Assumptions!$B$10-Assumptions!$B$9)/Assumptions!$B$6 | F7: =(SUMPRODUCT(DCF!$B$5:$K$5,1/(1+$A$7)^DCF!$B$6:$K$6)+DCF!$B$11*(1+F$4)*(1-F$4/DCF!$B$14)/($A$7-F$4)/(1+$A$7)^(10-0.5)-Assumptions!$B$10-Assumptions!$B$9)/Assumptions!$B$6
A8: 0.082962428 | B8: =(SUMPRODUCT(DCF!$B$5:$K$5,1/(1+$A$8)^DCF!$B$6:$K$6)+DCF!$B$11*(1+B$4)*(1-B$4/DCF!$B$14)/($A$8-B$4)/(1+$A$8)^(10-0.5)-Assumptions!$B$10-Assumptions!$B$9)/Assumptions!$B$6 | C8: =(SUMPRODUCT(DCF!$B$5:$K$5,1/(1+$A$8)^DCF!$B$6:$K$6)+DCF!$B$11*(1+C$4)*(1-C$4/DCF!$B$14)/($A$8-C$4)/(1+$A$8)^(10-0.5)-Assumptions!$B$10-Assumptions!$B$9)/Assumptions!$B$6 | D8: =(SUMPRODUCT(DCF!$B$5:$K$5,1/(1+$A$8)^DCF!$B$6:$K$6)+DCF!$B$11*(1+D$4)*(1-D$4/DCF!$B$14)/($A$8-D$4)/(1+$A$8)^(10-0.5)-Assumptions!$B$10-Assumptions!$B$9)/Assumptions!$B$6 | E8: =(SUMPRODUCT(DCF!$B$5:$K$5,1/(1+$A$8)^DCF!$B$6:$K$6)+DCF!$B$11*(1+E$4)*(1-E$4/DCF!$B$14)/($A$8-E$4)/(1+$A$8)^(10-0.5)-Assumptions!$B$10-Assumptions!$B$9)/Assumptions!$B$6 | F8: =(SUMPRODUCT(DCF!$B$5:$K$5,1/(1+$A$8)^DCF!$B$6:$K$6)+DCF!$B$11*(1+F$4)*(1-F$4/DCF!$B$14)/($A$8-F$4)/(1+$A$8)^(10-0.5)-Assumptions!$B$10-Assumptions!$B$9)/Assumptions!$B$6
A9: 0.090462428 | B9: =(SUMPRODUCT(DCF!$B$5:$K$5,1/(1+$A$9)^DCF!$B$6:$K$6)+DCF!$B$11*(1+B$4)*(1-B$4/DCF!$B$14)/($A$9-B$4)/(1+$A$9)^(10-0.5)-Assumptions!$B$10-Assumptions!$B$9)/Assumptions!$B$6 | C9: =(SUMPRODUCT(DCF!$B$5:$K$5,1/(1+$A$9)^DCF!$B$6:$K$6)+DCF!$B$11*(1+C$4)*(1-C$4/DCF!$B$14)/($A$9-C$4)/(1+$A$9)^(10-0.5)-Assumptions!$B$10-Assumptions!$B$9)/Assumptions!$B$6 | D9: =(SUMPRODUCT(DCF!$B$5:$K$5,1/(1+$A$9)^DCF!$B$6:$K$6)+DCF!$B$11*(1+D$4)*(1-D$4/DCF!$B$14)/($A$9-D$4)/(1+$A$9)^(10-0.5)-Assumptions!$B$10-Assumptions!$B$9)/Assumptions!$B$6 | E9: =(SUMPRODUCT(DCF!$B$5:$K$5,1/(1+$A$9)^DCF!$B$6:$K$6)+DCF!$B$11*(1+E$4)*(1-E$4/DCF!$B$14)/($A$9-E$4)/(1+$A$9)^(10-0.5)-Assumptions!$B$10-Assumptions!$B$9)/Assumptions!$B$6 | F9: =(SUMPRODUCT(DCF!$B$5:$K$5,1/(1+$A$9)^DCF!$B$6:$K$6)+DCF!$B$11*(1+F$4)*(1-F$4/DCF!$B$14)/($A$9-F$4)/(1+$A$9)^(10-0.5)-Assumptions!$B$10-Assumptions!$B$9)/Assumptions!$B$6

Sheet DDM
A1: Multi-stage dividend discount
A2: Dividends fade from the retention-implied growth to terminal g, at Ke.
A4: Current DPS (USD) | B4: 2.92
A5: Near-term dividend growth | B5: 0.06
A6: Terminal growth | B6: =Assumptions!$B$22
A7: Cost of equity (Ke) | B7: =WACC!$B$4
A9: Year | B9: Y1 | C9: Y2 | D9: Y3 | E9: Y4 | F9: Y5 | G9: Y6
A10: Growth (fade) | B10: =$B$5+($B$6-$B$5)*0/5 | C10: =$B$5+($B$6-$B$5)*1/5 | D10: =$B$5+($B$6-$B$5)*2/5 | E10: =$B$5+($B$6-$B$5)*3/5 | F10: =$B$5+($B$6-$B$5)*4/5 | G10: =$B$5+($B$6-$B$5)*5/5
A11: DPS | B11: =$B$4*(1+B10) | C11: =B11*(1+C10) | D11: =C11*(1+D10) | E11: =D11*(1+E10) | F11: =E11*(1+F10) | G11: =F11*(1+G10)
A12: PV of DPS | B12: =B11/(1+$B$7)^1 | C12: =C11/(1+$B$7)^2 | D12: =D11/(1+$B$7)^3 | E12: =E11/(1+$B$7)^4 | F12: =F11/(1+$B$7)^5 | G12: =G11/(1+$B$7)^6
A14: PV explicit dividends | B14: =SUM(B12:G12)
A15: PV terminal value | B15: =G11*(1+$B$6)/($B$7-$B$6)/(1+$B$7)^6
A16: Value per share | B16: =$B$14+$B$15

Sheet IS (reported)
A1: RTX — IS (reported)
A2: As reported by yfinance (USDmm). Hardcoded actuals.
A4: Line item | B4: FY2021 | C4: FY2022 | D4: FY2023 | E4: FY2024 | F4: FY2025
A5: Tax Effect Of Unusual Items | C5: 0 | D5: 0 | E5: 0 | F5: 0
A6: Tax Rate For Calcs | C6: 1.29e-07 | D6: 1.19e-07 | E6: 1.90668e-07 | F6: 1.90542e-07
A7: Normalized EBITDA | C7: 11525 | D7: 9700 | E7: 12528 | F7: 14946
A8: Total Unusual Items | B8: -649 | C8: 0 | D8: 0
A9: Total Unusual Items Excluding Goodwill | B9: -649 | C9: 0 | D9: 0
A10: Net Income From Continuing Operation Net Minority Interest | C10: 5216 | D10: 3195 | E10: 4774 | F10: 6732
A11: Reconciled Depreciation | C11: 4108 | D11: 4211 | E11: 4364 | F11: 4378
A12: Reconciled Cost Of Revenue | C12: 53406 | D12: 56831 | E12: 65328 | F12: 70814
A13: EBITDA | C13: 11525 | D13: 9700 | E13: 12528 | F13: 14946
A14: EBIT | C14: 7417 | D14: 5489 | E14: 8164 | F14: 10568
A15: Net Interest Income | C15: -1230 | D15: -1553 | E15: -1868 | F15: -1737
A16: Interest Expense | C16: 1300 | D16: 1653 | E16: 1970 | F16: 1835
A17: Interest Income | C17: 70 | D17: 100 | E17: 102 | F17: 98
A18: Normalized Income | C18: 5216 | D18: 3195 | E18: 4774 | F18: 6732
A19: Net Income From Continuing And Discontinued Operation | C19: 5197 | D19: 3195 | E19: 4774 | F19: 6732
A20: Total Expenses | C20: 61570 | D20: 65359 | E20: 74200 | F20: 79303
A21: Total Operating Income As Reported | C21: 5504 | D21: 3561 | E21: 6538 | F21: 9300
... A30: Net Income Including Noncontrolling Interests | C30: 5308 | D30: 3380 | E30: 5013 | F30: 7069
A31: Net Income Discontinuous Operations | B31: -33 | C31: -19 | D31: 0 | E31: 0
A32: Net Income Continuous Operations | C32: 5327 | D32: 3380 | E32: 5013 | F32: 7069
A33: Tax Provision | C33: 790 | D33: 456 | E33: 1181 | F33: 1664
A34: Pretax Income | C34: 6117 | D34: 3836 | E34: 6194 | F34: 8733
A35: Other Income Expense | C35: 1843 | D35: 1828 | E35: 1524 | F35: 1170
A36: Other Non Operating Income Expenses | C36: 1843 | D36: 1828 | E36: 1524 | F36: 1170
A37: Special Income Charges | B37: -649 | C37: 0 | D37: 0
A38: Other Special Charges | B38: 649
A39: Impairment Of Capital Assets | B39: 0 | C39: 0
A40: Net Non Operating Interest Income Expense | C40: -1230 | D40: -1553 | E40: -1868 | F40: -1737
A41: Interest Expense Non Operating | C41: 1300 | D41: 1653 | E41: 1970 | F41: 1835
A42: Interest Income Non Operating | C42: 70 | D42: 100 | E42: 102 | F42: 98
A43: Operating Income | C43: 5504 | D43: 3561 | E43: 6538 | F43: 9300
A44: Operating Expense | C44: 8164 | D44: 8528 | E44: 8872 | F44: 8489
A45: Other Operating Expenses | C45: -120 | D45: -86 | E45: 132 | F45: -413
A46: Research And Development | C46: 2711 | D46: 2805 | E46: 2934 | F46: 2807
A47: Selling General And Administration | C47: 5573 | D47: 5809 | E47: 5806 | F47: 6095
A48: General And Administrative Expense | B48: 3102 | C48: 3684 | D48: 4029
A49: Other Gand A | B49: 5046 | C49: 5573 | D49: 5809
...

Sheet BS (reported)
A1: RTX — BS (reported)
A2: As reported by yfinance (USDmm). Hardcoded actuals.
A4: Line item | B4: FY2021 | C4: FY2022 | D4: FY2023 | E4: FY2024 | F4: FY2025
A5: Treasury Shares Number | C5: 244.72 | D5: 385.81 | E5: 386.633 | F5: 383.025
A6: Ordinary Shares Number | C6: 1466.24 | D6: 1326.907 | E6: 1332.1228 | F6: 1342.2877
A7: Share Issued | C7: 1710.96 | D7: 1712.717 | E7: 1718.7558 | F7: 1725.3127
A8: Net Debt | C8: 25694 | D8: 37240 | E8: 35683 | F8: 30469
A9: Total Debt | C9: 33500 | D9: 45239 | E9: 42893 | F9: 39506
A10: Tangible Book Value | C10: -18031 | D10: -29300 | E10: -26076 | F10: -19943
A11: Invested Capital | C11: 104546 | D11: 103625 | E11: 101417 | F11: 103149
A12: Working Capital | C12: 3329 | D12: 1656 | E12: -366 | F12: 1548
A13: Net Tangible Assets | C13: -18031 | D13: -29300 | E13: -26076 | F13: -19943
A14: Capital Lease Obligations | C14: 1586 | D14: 1412 | E14: 1632 | F14: 1602
A15: Common Stock Equity | C15: 72632 | D15: 59798 | E15: 60156 | F15: 65245
A16: Total Capitalization | C16: 103326 | D16: 102153 | E16: 98882 | F16: 99533
... A19: Stockholders Equity | C19: 72632 | D19: 59798 | E19: 60156 | F19: 65245
A20: Other Equity Interest | B20: -38 | C20: -28 | D20: -15
A21: Gains Losses Not Affecting Retained Earnings | C21: -2018 | D21: -2419 | E21: -3755 | F21: -2718
A22: Other Equity Adjustments | C22: -2018 | D22: -2419 | E22: -3755 | F22: -2718
A23: Treasury Stock | C23: 15530 | D23: 26977 | E23: 27112 | F23: 26881
A24: Retained Earnings | C24: 52269 | D24: 52154 | E24: 53589 | F24: 56718
A25: Capital Stock | C25: 37939 | D25: 37055 | E25: 37434 | F25: 38126
A26: Common Stock | C26: 37939 | D26: 37055 | E26: 37434 | F26: 38126
A27: Preferred Stock | C27: 0 | D27: 0 | E27: 0 | F27: 0
A28: Total Liabilities Net Minority Interest | C28: 84650 | D28: 100424 | E28: 100903 | F28: 103941
A29: Total Non Current Liabilities Net Minority Interest | C29: 45536 | D29: 53663 | E29: 49404 | F29: 45157
A30: Other Non Current Liabilities | C30: 8449 | D30: 7511 | E30: 6942 | F30: 7200
A31: Employee Benefits | C31: 4807 | D31: 2385 | E31: 2104 | F31: 2067
A32: Non Current Pension And Other Postretirement Benefit Plans | C32: 4807 | D32: 2385 | E32: 2104 | F32: 2067
... A40: Current Debt | C40: 1220 | D40: 1472 | E40: 2535 | F40: 3616
A41: Other Current Borrowings | B41: 158 | C41: 696
A42: Commercial Paper | B42: 0 | C42: 524
A43: Pensionand Other Post Retirement Benefit Plans Current | C43: 2401 | D43: 2491 | E43: 2620 | F43: 3308
A44: Payables And Accrued Expenses | C44: 20895 | D44: 25615 | E44: 27728 | F44: 30245
A45: Current Accrued Expenses | C45: 10999 | D45: 14917 | E45: 14831 | F45: 14350
A46: Payables | C46: 9896 | D46: 10698 | E46: 12897 | F46: 15895
A47: Accounts Payable | C47: 9896 | D47: 10698 | E47: 12897 | F47: 15895
A48: Total Assets | C48: 158864 | D48: 161869 | E48: 162861 | F48: 171079
A49: Total Non Current Assets | C49: 116421 | D49: 113452 | E49: 111728 | F49: 110747
A50: Other Non Current Assets | C50: 6156 | D50: 4576 | E50: 5297 | F50: 4672
...

Sheet CF (reported)
A1: RTX — CF (reported)
A2: As reported by yfinance (USDmm). Hardcoded actuals.
A4: Line item | B4: FY2021 | C4: FY2022 | D4: FY2023 | E4: FY2024 | F4: FY2025
A5: Free Cash Flow | C5: 4393 | D5: 4717 | E5: 3923 | F5: 7448
A6: Repurchase Of Capital Stock | C6: -2803 | D6: -12870 | E6: -444 | F6: -50
A7: Repayment Of Debt | C7: -3 | D7: -10578 | E7: -2500 | F7: -3429
A8: Issuance Of Debt | C8: 1 | D8: 22914 | E8: 0 | F8: 0
A9: Capital Expenditure | C9: -2775 | D9: -3166 | E9: -3236 | F9: -3119
A10: Interest Paid Supplemental Data | C10: 1263 | D10: 1464 | E10: 1942 | F10: 1858
A11: Income Tax Paid Supplemental Data | C11: 2400 | D11: 1527 | E11: 1176 | F11: 1607
A12: End Cash Position | C12: 6220 | D12: 6587 | E12: 5578 | F12: 7435
A13: Other Cash Adjustment Outside Changein Cash | C13: -71 | D13: -39 | E13: -28 | F13: -35
A14: Beginning Cash Position | C14: 7853 | D14: 6291 | E14: 6626 | F14: 5606
A15: Effect Of Exchange Rate Changes | C15: -42 | D15: 18 | E15: -28 | F15: 48
A16: Changes In Cash | C16: -1520 | D16: 317 | E16: -992 | F16: 1816
A17: Financing Cash Flow | C17: -5859 | D17: -4527 | E17: -6617 | F17: -7486
A18: Cash From Discontinued Financing Activities | B18: 0 | C18: 0 | D18: 0
A19: Cash Flow From Continuing Financing Activities | C19: -5859 | D19: -4527 | E19: -6617 | F19: -7486
A20: Net Other Financing Charges | C20: -415 | D20: -230 | E20: -456 | F20: -433
A21: Proceeds From Stock Option Exercised | B21: 7
A22: Cash Dividends Paid | C22: -3128 | D22: -3239 | E22: -3217 | F22: -3574
A23: Common Stock Dividend Paid | C23: -3128 | D23: -3239 | E23: -3217 | F23: -3574
A24: Net Common Stock Issuance | C24: -2803 | D24: -12870 | E24: -444 | F24: -50
A25: Common Stock Payments | C25: -2803 | D25: -12870 | E25: -444 | F25: -50
A26: Net Issuance Payments Of Debt | C26: 487 | D26: 11812 | E26: -2500 | F26: -3429
A27: Net Short Term Debt Issuance | C27: 489 | D27: -524 | E27: 0 | F27: 0
A28: Net Long Term Debt Issuance | C28: -2 | D28: 12336 | E28: -2500 | F28: -3429
A29: Long Term Debt Payments | C29: -3 | D29: -10578 | E29: -2500 | F29: -3429
A30: Long Term Debt Issuance | C30: 1 | D30: 22914 | E30: 0 | F30: 0
A31: Investing Cash Flow | C31: -2829 | D31: -3039 | E31: -1534 | F31: -1265
A32: Cash From Discontinued Investing Activities | B32: 0 | C32: 0 | D32: 0
A33: Cash Flow From Continuing Investing Activities | C33: -2829 | D33: -3039 | E33: -1534 | F33: -1265
A34: Net Other Investing Changes | C34: 94 | D34: 12 | E34: 65 | F34: -123
A35: Net Investment Purchase And Sale | C35: -176 | D35: 109 | E35: -158 | F35: 46
A36: Sale Of Investment | C36: 179 | D36: 226 | E36: 202 | F36: 279
A37: Purchase Of Investment | C37: -355 | D37: -117 | E37: -360 | F37: -233
A38: Net Business Purchase And Sale | C38: 28 | D38: 6 | E38: 1795 | F38: 1931
A39: Sale Of Business | C39: 94 | D39: 6 | E39: 1795 | F39: 1931
A40: Purchase Of Business | B40: -1088 | C40: -66 | D40: 0 | E40: 0
A41: Net Intangibles Purchase And Sale | C41: -487 | D41: -751 | E41: -611 | F41: -492
...
